Workbook

Sheet PVT
A1: selection1 | B1: (All)
A2: selection2 | B2: (All)
A3: name | B3: (All)
A4: Years (start_date) | B4: (Multiple Items)
A5: Quarters (start_date) | B5: (All)
A6: Months (start_date) | B6: (All)
A7: selection3 | B7: (All)
A8: asset type | B8: ETF
A9: currency | B9: USD
A11: Row Labels | B11: Count of ticker
A12: Bonds | B12: 8
A13: Equity | B13: 31
A14: Agriculture | B14: 5
A15: Energy | B15: 6
A16: Metals | B16: 4
A17: Grand Total | B17: 54

Sheet Asset_list
A1: asset type | B1: asset_class | C1: Tracker | D1: ticker | E1: name | F1: currency | G1: exchange | H1: start_date | I1: selection1 | J1: selection2 | K1: selection3
A2: ETF | B2: Agriculture | C2: Agriculture | D2: DBA | E2: Invesco DB Agriculture Fund | F2: USD | G2: NYSEArca | H2: =VLOOKUP(D2,yahooData!A:F,3,FALSE) -> 40462 | I2: X | J2: X | K2: X
A3: ETF | B3: Agriculture | C3: Sugar | D3: CANE | E3: Teucrium Sugar Fund | F3: USD | G3: NYSEArca | H3: =VLOOKUP(D3,yahooData!A:F,3,FALSE) -> 40805 | I3: X | J3: X | K3: X
A4: ETF | B4: Agriculture | C4: Corn | D4: CORN | E4: Teucrium Corn Fund | F4: USD | K4: X
A5: ETF | B5: Agriculture | C5: Wheat | D5: WEAT | E5: Teucrium Wheat Fund | F5: USD | K5: X
A6: ETF | B6: Agriculture | C6: Soybeans | D6: SOYB | E6: Teucrium Soybean Fund | F6: USD | K6: X
A7: ETF | B7: Agriculture | C7: Agriculture | D7: FAAR | E7: First Trust Alternative Absolute Return Strategy ETF | F7: USD | H7: 42513
A8: ETF | B8: Bonds | C8: US Bonds 20y | D8: TLT | E8: iShares 20+ Year Treasury Bond ETF | F8: USD | G8: NasdaqGM | H8: =VLOOKUP(D8,yahooData!A:F,3,FALSE) -> 40462 | K8: X
A9: ETF | B9: Bonds | C9: US Bonds 10y | D9: TLH | E9: iShares 10-20 Year Treasury Bond ETF | F9: USD | G9: NYSEArca | H9: =VLOOKUP(D9,yahooData!A:F,3,FALSE) -> 40462 | I9: X | J9: X | K9: X
A10: ETF | B10: Bonds | C10: US Bonds 7y | D10: IEF | E10: iShares 7-10 Year Treasury Bond ETF | F10: USD | G10: NasdaqGM | H10: =VLOOKUP(D10,yahooData!A:F,3,FALSE) -> 40462 | K10: X
A11: ETF | B11: Bonds | C11: Euro Bonds | D11: EXHF.DE | E11: IShares Euro Government Bond Capped 1.5y-10.5y UCITS ETF | F11: EUR | G11: XETRA | H11: =VLOOKUP(D11,yahooData!A:F,3,FALSE) -> 40462 | I11: X
A12: ETF | B12: Bonds | C12: German Bonds | D12: GGOV | E12: iShares Global Government Bond USD Hedged Active ETF | F12: USD | G12: NYSEArca | H12: =VLOOKUP(D12,yahooData!A:F,3,FALSE) -> 45834
A13: ETF | B13: Bonds | C13: US Bonds 1y | D13: ISTB | E13: iShares Core 1-5 Year USD Bond ETF | F13: USD | G13: NasdaqGM | H13: =VLOOKUP(D13,yahooData!A:F,3,FALSE) -> 41206 | J13: X | K13: X
A14: ETF | B14: Bonds | C14: French Bonds | D14: IFRB.L | E14: iShares France Govt Bond UCITS ETF EUR (Dist) (IFRB.L) | F14: EUR | G14: LSE | H14: =VLOOKUP(D14,yahooData!A:F,3,FALSE) -> 41037 | I14: X
A15: ETF | B15: Bonds | C15: Italian Bonds | D15: BTP10.MI | E15: Amundi Italy BTP Government Bond 10Y UCITS ETF Acc | F15: EUR | G15: Euronext Milan | H15: =VLOOKUP(D15,yahooData!A:F,3,FALSE) -> 45341
A16: ETF | B16: Bonds | C16: UK Bonds | D16: IGLT.L | E16: iShares Core UK Gilts UCITS ETF GBP | F16: GBP | G16: LSE | H16: =VLOOKUP(D16,yahooData!A:F,3,FALSE) -> 40462 | I16: X
A17: ETF | B17: Bonds | C17: US Bonds 1y | D17: IBC1.MU | E17: iShares USD Treasury Bond 0-1yr UCITS ETF | F17: EUR | G17: Munich | H17: =VLOOKUP(D17,yahooData!A:F,3,FALSE) -> 43521
A18: ETF | B18: Bonds | C18: US Bonds 0y | D18: IBCC.MU | E18: Ishares Treasury Bond 0-1 year UCITS ETF | F18: EUR | G18: Munich | H18: =VLOOKUP(D18,yahooData!A:F,3,FALSE) -> 45933
A19: ETF | B19: Bonds | C19: US Bonds 3y | D19: CBU7L.XC | E19: iShares USD Treasury Bond 3-7yr | F19: USD?? | G19: CBOE UK | H19: =VLOOKUP(D19,yahooData!A:F,3,FALSE) -> 45932
A20: ETF | B20: Bonds | C20: US Bonds 3y | D20: SXRL.DE | E20: iShares $ Treasury Bond 3-7yr UCITS ETF USD | F20: USD?? | G20: XETRA | H20: =VLOOKUP(D20,yahooData!A:F,3,FALSE) -> 45684
A21: ETF | B21: Bonds | C21: US Bonds 0y | D21: SGOV | E21: iShares 0-3 Month Treasury Bond ETF | F21: USD | G21: NYSEArca | H21: =VLOOKUP(D21,yahooData!A:F,3,FALSE) -> 43983
A22: ETF | B22: Bonds | C22: US Bonds | D22: GOVI | E22: Invesco Equal Weight 0-30 Years Treasury ETF | F22: USD | G22: NasdaqGM | H22: =VLOOKUP(D22,yahooData!A:F,3,FALSE) -> 40462 | K22: X
A23: ETF | B23: Bonds | C23: Chinese Bonds | D23: CBON | F23: USD | H23: =VLOOKUP(D23,yahooData!A:F,3,FALSE) -> 41954 | J23: X
A24: ETF | B24: Bonds | C24: Emerging market Bonds | D24: EMB | E24: iShares J.P. Morgan USD Emerging Markets Bond ETF | F24: USD | G24: NasdaqGM | H24: =VLOOKUP(D24,yahooData!A:F,3,FALSE) -> 40462 | J24: X | K24: X
A25: ETF | B25: Bonds | C25: International Bonds | D25: BWX | E25: SPDR Bloomberg International Treasury Bond ETF | F25: USD | H25: =VLOOKUP(D25,yahooData!A:F,3,FALSE) -> 40462 | J25: X | K25: X
A26: ETF | B26: Bonds | C26: US Bonds short term | D26: VGSH | E26: Vanguard Short-Term Treasury ETF | F26: USD | H26: =VLOOKUP(D26,yahooData!A:F,3,FALSE) -> 40462 | J26: X | K26: X
A27: FUTURES | B27: Energy | C27: Crude Oil | D27: CL=F | E27: Crude Oil | F27: USD | G27: NY Merc | H27: =VLOOKUP(D27,yahooData!A:F,3,FALSE) -> 40462
A28: ETF | B28: Energy | C28: Crude Oil | D28: OILK | E28: ProShares K-1 Free Crude Oil ETF | F28: USD | G28: CBOE US | H28: =VLOOKUP(D28,yahooData!A:F,3,FALSE) -> 42641 | I28: X
A29: ETF | B29: Energy | C29: Crude Oil | D29: USO | E29: United States Oil Fund | F29: USD | H29: =VLOOKUP(D29,yahooData!A:F,3,FALSE) -> 40462 | J29: X | K29: X
A30: ETF | B30: Energy | C30: Crude Oil | D30: UCO | E30: ProShares Ultra Bloomberg Crude Oil | F30: USD | H30: =VLOOKUP(D30,yahooData!A:F,3,FALSE) -> 40462 | K30: X
A31: ETF | B31: Energy | C31: Natural Gas | D31: UNG | E31: United States Natural Gas Fund LP | F31: USD | K31: X
A32: ETF | B32: Energy | C32: Natural Gas | D32: BOIL | E32: ProShares Ultra Bloomberg Natural Gas | F32: USD | K32: X
A33: ETF | B33: Energy | C33: Carbon | D33: KRBN | E33: KraneShares Global Carbon Strategy ETF | F33: USD | H33: 44043
A34: ETF | B34: Energy | C34: Gasoline | D34: UGA | E34: United States Gasoline Fund LP | F34: USD | K34: X
A35: ETF | B35: Energy | C35: Energy | D35: DBE | E35: Invesco DB Energy Fund | F35: USD | K35: X
A36: ETF | B36: Equity | C36: SP500 | D36: SPY | E36: SPDR S&P 500 | F36: USD | G36: NYSEArca | H36: =VLOOKUP(D36,yahooData!A:F,3,FALSE) -> 40462 | I36: X | J36: X | K36: X
A37: ETF | B37: Equity | C37: NASDAQ100 | D37: QQQ | E37: Invesco QQQ Trust, Series 1 | F37: USD | G37: NasdaqGM | H37: =VLOOKUP(D37,yahooData!A:F,3,FALSE) -> 40462 | K37: X
A38: ETF | B38: Equity | C38: World | D38: URTH | E38: iShares MSCI World | F38: USD | G38: NYSEArca | H38: =VLOOKUP(D38,yahooData!A:F,3,FALSE) -> 40920 | K38: X
A39: ETF | B39: Equity | C39: Emerging | D39: EEM | E39: iShares MSCI Emerging Markets ETF | F39: USD | G39: NYSEArca | H39: =VLOOKUP(D39,yahooData!A:F,3,FALSE) -> 40462 | K39: X
A40: ETF | B40: Equity | C40: Japan | D40: EWJ | E40: iShares MSCI Japan ETF | F40: USD | G40: NYSEArca | H40: =VLOOKUP(D40,yahooData!A:F,3,FALSE) -> 40462 | I40: X | K40: X
...

Sheet yahooData
A1: Symbol | B1: Name | C1: Earliest | D1: Latest | E1: fundFamily | F1: fundInceptionDate
A2: OILK | B2: ProShares K-1 Free Crude Oil ET | C2: 42641 | D2: 45933 | E2: ProShares | F2: 42639
A3: CPER | B3: United States Copper Index Fund | C3: 40862 | D3: 45933 | E3: USCF Investments | F3: 40861
A4: SLV | B4: iShares Silver Trust | C4: 40462 | D4: 45933 | E4: iShares | F4: 38828
A5: URTH | B5: iShares, Inc. iShares MSCI Worl | C5: 40920 | D5: 45933 | E5: iShares | F5: 40918
A6: AIA | B6: iShares Asia 50 ETF | C6: 40462 | D6: 45933 | E6: iShares | F6: 39399
A7: SPY | B7: SPDR S&P 500 | C7: 40462 | D7: 45933 | E7: SPDR State Street Investment Management | F7: 33991
A8: BWX | B8: SPDR Bloomberg International Tr | C8: 40462 | D8: 45933 | E8: SPDR State Street Investment Management | F8: 39357
A9: USO | B9: United States Oil Fund | C9: 40462 | D9: 45933 | E9: USCF Investments | F9: 38817
A10: ETH=F | B10: Ether Futures,Oct-2025 | C10: 44232 | D10: 45933
A11: IFRB.L | B11: ISHARES V PUBLIC LIMITED COMPAN | C11: 41037 | D11: 45933 | E11: BlackRock Asset Management Ireland - ETF | F11: 44841
A12: EWU | B12: iShares MSCI | C12: 40462 | D12: 45933 | E12: iShares | F12: 35136
A13: ECH | B13: iShares Inc. iShares MSCI Chile | C13: 40462 | D13: 45933 | E13: iShares | F13: 39398
A14: VGSH | B14: Vanguard Short-Term Treasury ET | C14: 40462 | D14: 45933 | E14: Vanguard | F14: 40413
A15: EWY | B15: iShares Inc iShares MSCI South | C15: 40462 | D15: 45933 | E15: iShares | F15: 36655
A16: SW2CHB.SW | B16: UBSETF MSCICHL CHFa | C16: 41578 | D16: 45933 | E16: UBS Asset Management (Europe) S.A. | F16: 44006
A17: ISTB | B17: iShares Core 1-5 Year USD Bond | C17: 41206 | D17: 45933 | E17: iShares | F17: 41200
A18: ILC.AX | B18: ISHLGECAP ISHLGECAP [ILC] | C18: 40519 | D18: 45933 | E18: BlackRock Investment Management (Australia) Limited | F18: 40518
A19: MCHI | B19: iShares MSCI China ETF | C19: 40633 | D19: 45933 | E19: iShares | F19: 40631
A20: EMB | B20: iShares J.P. Morgan USD Emergin | C20: 40462 | D20: 45933 | E20: iShares | F20: 39433
A21: EWW | B21: iShares Inc iShares MSCI Mexico | C21: 40462 | D21: 45933 | E21: iShares | F21: 35136
A22: EPOL | B22: iShares Trust iShares MSCI Pola | C22: 40462 | D22: 45933 | E22: iShares | F22: 40323
A23: IBC1.MU | B23: iShs DL Treas.Bd 0-1yr UC.ETF R | C23: 43521 | D23: 45933
A24: SXRL.DE | B24: iShs VII-$ Trsy Bd 3-7yr U.ETFR | C24: 45684 | D24: 45933 | E24: BlackRock Asset Management Ireland - ETF | F24: 39967
A25: GC=F | B25: Gold Dec 25 | C25: 40462 | D25: 45933
A26: FEZ | B26: SPDR DJ Euro STOXX 50 Etf | C26: 40462 | D26: 45933 | E26: SPDR State Street Investment Management | F26: 37544
A27: BTP10.MI | B27: Amundi Ita BTP Govmnt Bnd 10Y U | C27: 45341 | D27: 45933 | E27: Amundi Luxembourg S.A. | F27: 45341
A28: IBIT | B28: iShares Bitcoin Trust ETF - iSh | C28: 45302 | D28: 45933 | E28: iShares | F28: 45296
A29: GGOV | B29: BlackRock ETF Trust II iShares | C29: 45834 | D29: 45933 | E29: iShares | F29: 45833
A30: EXS1.DE | B30: iShares Core DAX UCITS ETF DE I | C30: 40462 | D30: 45933 | E30: BlackRock Asset Management Deutschland AG - ETF | F30: 36887
A31: TLH | B31: iShares 10-20 Year Treasury Bon | C31: 40462 | D31: 45933 | E31: iShares | F31: 39087
A32: BITO | B32: ProShares Bitcoin ETF | C32: 44489 | D32: 45933 | E32: ProShares | F32: 44487
A33: EWL | B33: iShares Inc iShares MSCI Switze | C33: 40462 | D33: 45933 | E33: iShares | F33: 35136
A34: VGK | B34: Vanguard FTSEEuropean ETF | C34: 40462 | D34: 45933 | E34: Vanguard | F34: 37116
A35: STW.AX | B35: SPDR 200 ETF UNITS [STW] | C35: 40462 | D35: 45933 | E35: State Street Global Advisors (Aus) Ltd | F35: 37127
A36: ILF | B36: iShares Latin America 40 ETF | C36: 40462 | D36: 45933 | E36: iShares | F36: 37189
A37: IEF | B37: iShares 7-10 Year Treasury Bond | C37: 40462 | D37: 45933 | E37: iShares | F37: 37459
... A48: TUR | B48: iShares MSCI Turkey ETF | C48: 40462 | D48: 45933 | E48: iShares | F48: 39533
A49: CBU7L.XC | B49: iShares USD Treasury Bond 3-7yr | C49: 45932 | D49: 45932
A50: CACC.PA | B50: Amundi CAC 40 UCITS ETF Acc | C50: 43447 | D50: 45933 | E50: Amundi Asset Management | F50: 45811
...

Sheet selection3
A1: ticker | B1: asset_class | C1: Tracker | D1: name
A2: DBA | B2: Agriculture | C2: Agriculture | D2: Invesco DB Agriculture Fund
A3: CANE | B3: Agriculture | C3: Sugar | D3: Teucrium Sugar Fund
A4: CORN | B4: Agriculture | C4: Corn | D4: Teucrium Corn Fund
A5: WEAT | B5: Agriculture | C5: Wheat | D5: Teucrium Wheat Fund
A6: SOYB | B6: Agriculture | C6: Soybeans | D6: Teucrium Soybean Fund
A7: TLT | B7: Bonds | C7: US Bonds 20y | D7: iShares 20+ Year Treasury Bond ETF
A8: TLH | B8: Bonds | C8: US Bonds 10y | D8: iShares 10-20 Year Treasury Bond ETF
A9: IEF | B9: Bonds | C9: US Bonds 7y | D9: iShares 7-10 Year Treasury Bond ETF
A10: ISTB | B10: Bonds | C10: US Bonds 1y | D10: iShares Core 1-5 Year USD Bond ETF
A11: GOVI | B11: Bonds | C11: US Bonds | D11: Invesco Equal Weight 0-30 Years Treasury ETF
A12: EMB | B12: Bonds | C12: Emerging market Bonds | D12: iShares J.P. Morgan USD Emerging Markets Bond ETF
... A55: CPER | B55: Metals | C55: Copper | D55: United States Copper Index Fund
